<?xml version="1.0" ?>
  <robot name="opensg_robot" xmlns:xacro="http://ros.org/wiki/xacro">
  <xacro:include filename="$(find robot_description)/urdf/common_properties.xacro"/>
  <xacro:include filename="$(find robot_description)/urdf/opensg_robot.gazebo.mesh.xacro"/> 

  <link name="base_footprint"/>

  <joint name="base_joint" type="fixed">
    <parent link="base_footprint"/>
    <child link="base_link" />
    <origin xyz="0 0 0.03" rpy="0 0 0"/>
  </joint>

  <link name="base_link">
    <visual>
      <origin xyz = "0 0 0" rpy = "1.570796 0 3.141592"/>
      <geometry>
        <mesh filename="package://robot_description/mesh/robot_base.stl" scale="0.001 0.001 0.001"/>
      </geometry>
      <material name="grey"/>
    </visual>

    <collision>
      <origin xyz = "0 0 0.03" rpy = "1.570796 0 3.141592"/>
      <geometry>
        <mesh filename="package://robot_description/mesh/robot_base.stl" scale="0.001 0.001 0.001"/>
      </geometry>
    </collision>

    <inertial>
      <origin xyz="0 0 0" rpy="0 0 0"/>
      <mass value="1.3729096e+00"/>
      <inertia ixx="8.7002718e-03" ixy="-4.7576583e-05" ixz="1.1160499e-04"
              iyy="8.6195418e-03" iyz="-3.5422299e-06"
              izz="1.4612727e-02" />
    </inertial>
  </link>

  <joint name = "front_caster_left_joint" type = "fixed">
    <parent link = "base_link" />
    <child link = "front_caster_left" />
    <origin xyz = "0.5 -0.15 0.089" rpy = "0 0 3.141592"/>
  </joint>

  <link name="front_caster_left">
    <visual>
      <origin xyz = "0 0 0" rpy = "0 0 0"/>
      <geometry>
        <mesh filename="package://robot_description/mesh/robot_caster.stl" scale="0.001 0.001 0.001"/>
      </geometry>
      <material name="white"/>
    </visual>

    <collision>
      <origin xyz = "0 0 0" rpy = "0 0 0"/>
      <geometry>
        <mesh filename="package://robot_description/mesh/robot_caster.stl" scale="0.001 0.001 0.001"/>
      </geometry>
    </collision>

    <inertial>
      <origin xyz="0 0 0" />
      <mass value="0.005" />
      <inertia ixx="0.001" ixy="0.0" ixz="0.0"
              iyy="0.001" iyz="0.0"
              izz="0.001" />
    </inertial>
  </link>

  <joint name = "front_caster_right_joint" type = "fixed">
    <parent link = "base_link" />
    <child link = "front_caster_right" />
    <origin xyz = "0.5 0.15 0.089" rpy = "0 0 3.141592"/>
  </joint>

  <link name="front_caster_right">
    <visual>
      <origin xyz = "0 0 0" rpy = "0 0 0"/>
      <geometry>
        <mesh filename="package://robot_description/mesh/robot_caster.stl" scale="0.001 0.001 0.001"/>
      </geometry>
      <material name="white"/>
    </visual>

    <collision>
      <origin xyz = "0 0 0" rpy = "0 0 0"/>
      <geometry>
        <mesh filename="package://robot_description/mesh/robot_caster.stl" scale="0.001 0.001 0.001"/>
      </geometry>
    </collision>

    <inertial>
      <origin xyz="0 0 0" />
      <mass value="0.005" />
      <inertia ixx="0.001" ixy="0.0" ixz="0.0"
              iyy="0.001" iyz="0.0"
              izz="0.001" />
    </inertial>
  </link>


<joint name = "rear_caster_left_joint" type = "fixed">
    <parent link = "base_link" />
    <child link = "rear_caster_left" />
    <origin xyz = "-0.365 0.333 0.089" rpy = "0 0 3.141592"/>
  </joint>

  <link name="rear_caster_left">
    <visual>
      <origin xyz = "0 0 0" rpy = "0 0 0"/>
      <geometry>
        <mesh filename="package://robot_description/mesh/robot_caster.stl" scale="0.001 0.001 0.001"/>
      </geometry>
      <material name="white"/>
    </visual>

    <collision>
      <origin xyz = "0 0 0" rpy = "0 0 3.141592"/>
      <geometry>
        <mesh filename="package://robot_description/mesh/robot_caster.stl" scale="0.001 0.001 0.001"/>
      </geometry>
    </collision>

    <inertial>
      <origin xyz="0 0 0" />
      <mass value="0.005" />
      <inertia ixx="0.001" ixy="0.0" ixz="0.0"
              iyy="0.001" iyz="0.0"
              izz="0.001" />
    </inertial>
  </link>

  
  <joint name = "rear_caster_right_joint" type = "fixed">
    <parent link = "base_link" />
    <child link = "rear_caster_right" />
    <origin xyz = "-0.365 -0.333 0.089" rpy = "0 0 3.141592"/>
  </joint>

  <link name="rear_caster_right">
    <visual>
      <origin xyz = "0 0 0" rpy = "0 0 0"/>
      <geometry>
        <mesh filename="package://robot_description/mesh/robot_caster.stl" scale="0.001 0.001 0.001"/>
      </geometry>
      <material name="white"/>
    </visual>

    <collision>
      <origin xyz = "0 0 0" rpy = "0 0 3.141592"/>
      <geometry>
        <mesh filename="package://robot_description/mesh/robot_caster.stl" scale="0.001 0.001 0.001"/>
      </geometry>
    </collision>

    <inertial>
      <origin xyz="0 0 0" />
      <mass value="0.005" />
      <inertia ixx="0.001" ixy="0.0" ixz="0.0"
              iyy="0.001" iyz="0.0"
              izz="0.001" />
    </inertial>
  </link>


  <joint name="front_scan_joint" type="fixed">
    <parent link="base_link"/>
    <child link="front_base_scan"/>
    <origin xyz="0.545 -0.370 0.195" rpy="0 0 0"/>
  </joint>

  <link name="front_base_scan">
    <visual>
      <origin xyz="0 0 0" rpy="0 0 0"/>
      <geometry>
        <mesh filename="package://robot_description/mesh/lidar.stl" scale="0.001 0.001 0.001"/>
      </geometry>
    </visual>

    <collision>
      <origin xyz="0 0 0" rpy="0 0 0"/>
      <geometry>
        <mesh filename="package://robot_description/mesh/lidar.stl" scale="0.001 0.001 0.001"/>
      </geometry>
    </collision>

    <inertial>
      <mass value="0.114" />
      <origin xyz="0 0 0" />
      <inertia ixx="0.001" ixy="0.0" ixz="0.0"
               iyy="0.001" iyz="0.0"
               izz="0.001" />
    </inertial>
  </link>

  <joint name="rear_scan_joint" type="fixed">
    <parent link="base_link"/>
    <child link="rear_base_scan"/>
    <origin xyz="-0.545 0.370 0.195" rpy="0 0 3.1415"/>
  </joint>

  <link name="rear_base_scan">
    <visual>
      <origin xyz="0 0 0" rpy="0 0 0"/>
      <geometry>
        <mesh filename="package://robot_description/mesh/lidar.stl" scale="0.001 0.001 0.001"/>
      </geometry>
    </visual>

    <collision>
      <origin xyz="0 0 0" rpy="0 0 0"/>
      <geometry>
        <mesh filename="package://robot_description/mesh/lidar.stl" scale="0.001 0.001 0.001"/>
      </geometry>
    </collision>

    <inertial>
      <mass value="0.114" />
      <origin xyz="0 0 0" />
      <inertia ixx="0.001" ixy="0.0" ixz="0.0"
               iyy="0.001" iyz="0.0"
               izz="0.001" />
    </inertial>
  </link>

  <joint name = "left_wheel_joint" type = "continuous">
    <parent link = "base_link" />
    <child link = "left_wheel" />
    <origin xyz = "0 0.384 0.045" rpy = "0 0 0" />
    <axis xyz = "0 1 0" />
  </joint>

  <link name="left_wheel">
    <visual>
      <origin xyz="0 0 0" rpy="1.570796 0 0"/>
      <geometry>
        <cylinder radius = "0.08" length = "0.066" scale="0.0001 0.0001 0.0001"/>
      </geometry>
      <material name="red"/>
    </visual>

    <collision>
    <origin xyz="0 0 0" rpy="1.570796 0 0"/>
      <geometry>
        <cylinder radius = "0.08" length = "0.066"/>
      </geometry>
    </collision>

    <inertial>
      <origin xyz="0 0 0" />
      <mass value="2.8498940e-02" />
      <inertia ixx="1.1175580e-05" ixy="-4.2369783e-11" ixz="-5.9381719e-09"
              iyy="1.1192413e-05" iyz="-1.4400107e-11"
              izz="2.0712558e-05" />
    </inertial>
  </link>

  <joint name = "right_wheel_joint" type = "continuous">
    <parent link = "base_link" />
    <child link = "right_wheel" />
    <origin xyz = "0 -0.384 0.045" rpy = "0 0 0"/>
    <axis xyz = "0 1 0"/>
  </joint>

  <link name="right_wheel">
    <visual>
      <origin xyz="0 0 0" rpy="1.570796 0 0"/>
      <geometry>
        <cylinder radius = "0.08" length = "0.066" scale="0.0001 0.0001 0.0001"/>
      </geometry>
      <material name="red"/>
    </visual>

    <collision>
      <origin xyz="0 0 0" rpy="1.570796 0 0"/>
      <geometry>
        <cylinder radius = "0.08" length = "0.066"/>
      </geometry>
    </collision>

    <inertial>
      <origin xyz="0 0 0" />
      <mass value="2.8498940e-02" />
      <inertia ixx="1.1175580e-05" ixy="-4.2369783e-11" ixz="-5.9381719e-09"
              iyy="1.1192413e-05" iyz="-1.4400107e-11"
              izz="2.0712558e-05" />
    </inertial>
  </link>


  <!-- <joint name = "left_wheel_joint" type = "continuous">
    <parent link = "base_link" />
    <child link = "left_wheel" />
    <origin xyz = "0 0 0.16" rpy = "0 0 0"/>
    <axis xyz = "0 1 0" />
  </joint>

  <link name="left_wheel">
    <visual>
      <origin xyz="0 0 0" rpy="1.570796 0 0"/>
      <geometry>
        <mesh filename="package://robot_description/mesh/custom/wheel2.stl" scale="0.001 0.001 0.001"/>
      </geometry>
      <material name="red"/>
    </visual>

    <collision>
    <origin xyz="0 0 0" rpy="0 0 0"/>
      <geometry>
        <mesh filename="package://robot_description/mesh/custom/wheel2.stl" scale="0.001 0.001 0.001"/>
      </geometry>
    </collision>

    <inertial>
      <origin xyz="0 0 0" />
      <mass value="2.8498940e-02" />
      <inertia ixx="1.1175580e-05" ixy="-4.2369783e-11" ixz="-5.9381719e-09"
              iyy="1.1192413e-05" iyz="-1.4400107e-11"
              izz="2.0712558e-05" />
    </inertial>
  </link>


  <joint name = "right_wheel_joint" type = "continuous">
    <parent link = "base_link" />
    <child link = "right_wheel" />
    <origin xyz = "0 0 0.16" rpy = "0 0 0"/>
    <axis xyz = "0 1 0"/>
  </joint>

  <link name="right_wheel">
    <visual>
      <origin xyz="0 0 0" rpy="1.570796 0 0"/>
      <geometry>
        <mesh filename="package://robot_description/mesh/custom/wheel_0222.stl" scale="0.001 0.001 0.001"/>
      </geometry>
      <material name="red"/>
    </visual>

    <collision>
      <origin xyz="0 0 0" rpy="0 0 0"/>
      <geometry>
        <mesh filename="package://robot_description/mesh/custom/wheel_0222.stl" scale="0.001 0.001 0.001"/>
      </geometry>
    </collision>

    <inertial>
      <origin xyz="0 0 0" />
      <mass value="2.8498940e-02" />
      <inertia ixx="1.1175580e-05" ixy="-4.2369783e-11" ixz="-5.9381719e-09"
              iyy="1.1192413e-05" iyz="-1.4400107e-11"
              izz="2.0712558e-05" />
    </inertial>
  </link> -->

</robot>
