<?xml version="1.0" ?>
  <robot name="opensg_robot" xmlns:xacro="http://ros.org/wiki/xacro">
  <xacro:include filename="$(find robot_description)/urdf/common_properties.xacro"/>
  <xacro:include filename="$(find robot_description)/urdf/opensg_robot.gazebo.xacro"/> 

  <link name="base_footprint"/>

  <joint name="base_joint" type="fixed">
    <parent link="base_footprint"/>
    <child link="base_link" />
    <origin xyz="0 0 0" rpy="0 0 0"/>
  </joint>

  <link name="base_link">
    <visual>
      <origin xyz = "0 0 0.05" rpy = "0 0 0"/>
      <geometry>
        <box size = "0.4 0.2 0.1" />
      </geometry>
      <material name="grey"/>
    </visual>

    <collision>
      <origin xyz = "0 0 0.05" rpy = "0 0 0"/>
      <geometry>
        <box size = "0.4 0.2 0.1" />
      </geometry>
    </collision>

    <inertial>
      <origin xyz="0 0 0" rpy="0 0 0"/>
      <mass value="1.3729096e+00"/>
      <inertia ixx="8.7002718e-03" ixy="-4.7576583e-05" ixz="1.1160499e-04"
              iyy="8.6195418e-03" iyz="-3.5422299e-06"
              izz="1.4612727e-02" />
    </inertial>
  </link>

  <joint name = "front_caster_joint" type = "fixed">
    <parent link = "base_link" />
    <child link = "front_caster" />
    <origin xyz = "0.15 0 0" rpy = "1.57 0 0"/>
  </joint>

  <link name="front_caster">
    <visual>
      <origin xyz = "0 0 0" rpy = "0 0 0"/>
      <geometry>
        <sphere radius="0.05"/>
      </geometry>
      <material name="white"/>
    </visual>

    <collision>
      <origin xyz = "0.15 0 0" rpy = "1.57 0 0"/>
      <geometry>
        <sphere radius="0.05"/>
      </geometry>
    </collision>

    <inertial>
      <origin xyz="0 0 0" />
      <mass value="0.005" />
      <inertia ixx="0.001" ixy="0.0" ixz="0.0"
              iyy="0.001" iyz="0.0"
              izz="0.001" />
    </inertial>
  </link>

  <joint name="scan_joint" type="fixed">
    <parent link="base_link"/>
    <child link="base_scan"/>
    <origin xyz="0.08 0 0.122" rpy="0 0 0"/>
  </joint>

  <link name="base_scan">
    <visual>
      <origin xyz="0 0 0" rpy="0 0 0"/>
      <geometry>
        <cylinder length="0.0315" radius="0.055"/>
      </geometry>
    </visual>

    <collision>
      <origin xyz="0.015 0 -0.0065" rpy="0 0 0"/>
      <geometry>
        <cylinder length="0.0315" radius="0.055"/>
      </geometry>
    </collision>

    <inertial>
      <mass value="0.114" />
      <origin xyz="0 0 0" />
      <inertia ixx="0.001" ixy="0.0" ixz="0.0"
               iyy="0.001" iyz="0.0"
               izz="0.001" />
    </inertial>
  </link>

  <joint name = "left_wheel_joint" type = "continuous">
    <parent link = "base_link" />
    <child link = "left_wheel" />
    <origin xyz = "-0.1 0.125 0.05" rpy = "0 0 0" />
    <axis xyz = "0 1 0" />
  </joint>

  <link name="left_wheel">
    <visual>
      <origin xyz="0 0 0" rpy="1.57 0 0"/>
      <geometry>
        <cylinder radius = "0.1" length = "0.05"/>
      </geometry>
      <material name="red"/>
    </visual>

    <collision>
    <origin xyz="0 0 0" rpy="1.57 0 0"/>
      <geometry>
        <cylinder radius = "0.1" length = "0.05"/>
      </geometry>
    </collision>

    <inertial>
      <origin xyz="0 0 0" />
      <mass value="2.8498940e-02" />
      <inertia ixx="1.1175580e-05" ixy="-4.2369783e-11" ixz="-5.9381719e-09"
              iyy="1.1192413e-05" iyz="-1.4400107e-11"
              izz="2.0712558e-05" />
    </inertial>
  </link>

  <joint name = "right_wheel_joint" type = "continuous">
    <parent link = "base_link" />
    <child link = "right_wheel" />
    <origin xyz = "-0.1 -0.125 0.05" rpy = "0 0 0"/>
    <axis xyz = "0 1 0"/>
  </joint>

  <link name="right_wheel">
    <visual>
      <origin xyz="0 0 0" rpy="1.57 0 0"/>
      <geometry>
        <cylinder radius = "0.1" length = "0.05"/>
      </geometry>
      <material name="red"/>
    </visual>

    <collision>
      <origin xyz="0 0 0" rpy="1.57 0 0"/>
      <geometry>
        <cylinder radius = "0.1" length = "0.05"/>
      </geometry>
    </collision>

    <inertial>
      <origin xyz="0 0 0" />
      <mass value="2.8498940e-02" />
      <inertia ixx="1.1175580e-05" ixy="-4.2369783e-11" ixz="-5.9381719e-09"
              iyy="1.1192413e-05" iyz="-1.4400107e-11"
              izz="2.0712558e-05" />
    </inertial>
  </link>
</robot>
